Workbook

Sheet Flight_inventory
A1: Date | B1: Hub | C1: Flight number | D1: Pilot | E1: Heli manager | F1: Going to the plot? | G1: Extra weight (lbs)? | H1: Hazardous materials | I1: Drop off | J1: Plot | K1: Phone | L1: Crew leader | M1: Crew member 1 | N1: Crew member 2 | O1: Crew member 3 | P1: Crew member 4 | Q1: Notes
C2: 1 | I2: 1
A3: =IF(ISBLANK(J3),"",A$2) | B3: =IF(ISBLANK(J3),"",B$2) | C3: =IF(ISBLANK(J3),"",C$2) | D3: =IF(ISBLANK(J3),"",D$2) | E3: =IF(ISBLANK(J3),"",E$2) | F3: =IF(ISBLANK(J3),"",F$2) | G3: =IF(ISBLANK(J3),"",IF(ISBLANK(G$2),"",G$2)) | H3: =IF(ISBLANK(J3),"",IF(ISBLANK(H$2),"",H$2)) | I3: 2
A4: =IF(ISBLANK(J4),"",A$2) | B4: =IF(ISBLANK(J4),"",B$2) | C4: =IF(ISBLANK(J4),"",C$2) | D4: =IF(ISBLANK(J4),"",D$2) | E4: =IF(ISBLANK(J4),"",E$2) | F4: =IF(ISBLANK(J4),"",F$2) | G4: =IF(ISBLANK(J4),"",IF(ISBLANK(G$2),"",G$2)) | H4: =IF(ISBLANK(J4),"",IF(ISBLANK(H$2),"",H$2)) | I4: 3
A5: =IF(ISBLANK(J5),"",A$2) | B5: =IF(ISBLANK(J5),"",B$2) | C5: =IF(ISBLANK(J5),"",C$2) | D5: =IF(ISBLANK(J5),"",D$2) | E5: =IF(ISBLANK(J5),"",E$2) | F5: =IF(ISBLANK(J5),"",F$2) | G5: =IF(ISBLANK(J5),"",IF(ISBLANK(G$2),"",G$2)) | H5: =IF(ISBLANK(J5),"",IF(ISBLANK(H$2),"",H$2)) | I5: 4
A6: =IF(ISBLANK(J6),"",A$2) | B6: =IF(ISBLANK(J6),"",B$2) | C6: =IF(ISBLANK(J6),"",C$2) | D6: =IF(ISBLANK(J6),"",D$2) | E6: =IF(ISBLANK(J6),"",E$2) | F6: =IF(ISBLANK(J6),"",F$2) | G6: =IF(ISBLANK(J6),"",IF(ISBLANK(G$2),"",G$2)) | H6: =IF(ISBLANK(J6),"",IF(ISBLANK(H$2),"",H$2)) | I6: 5
A7: =IF(ISBLANK(E7),"",A$2) | C7: 2 | I7: 1
A8: =IF(ISBLANK(J8),"",A$7) | B8: =IF(ISBLANK(J8),"",B$7) | C8: =IF(ISBLANK(J8),"",C$7) | D8: =IF(ISBLANK(J8),"",D$7) | E8: =IF(ISBLANK(J8),"",E$7) | F8: =IF(ISBLANK(J8),"",F$7) | G8: =IF(ISBLANK(J8),"",IF(ISBLANK(G$7),"",G$7)) | H8: =IF(ISBLANK(J8),"",IF(ISBLANK(H$7),"",H$7)) | I8: 2
A9: =IF(ISBLANK(J9),"",A$7) | B9: =IF(ISBLANK(J9),"",B$7) | C9: =IF(ISBLANK(J9),"",C$7) | D9: =IF(ISBLANK(J9),"",D$7) | E9: =IF(ISBLANK(J9),"",E$7) | F9: =IF(ISBLANK(J9),"",F$7) | G9: =IF(ISBLANK(J9),"",IF(ISBLANK(G$7),"",G$7)) | H9: =IF(ISBLANK(J9),"",IF(ISBLANK(H$7),"",H$7)) | I9: 3
A10: =IF(ISBLANK(J10),"",A$7) | B10: =IF(ISBLANK(J10),"",B$7) | C10: =IF(ISBLANK(J10),"",C$7) | D10: =IF(ISBLANK(J10),"",D$7) | E10: =IF(ISBLANK(J10),"",E$7) | F10: =IF(ISBLANK(J10),"",F$7) | G10: =IF(ISBLANK(J10),"",IF(ISBLANK(G$7),"",G$7)) | H10: =IF(ISBLANK(J10),"",IF(ISBLANK(H$7),"",H$7)) | I10: 4
A11: =IF(ISBLANK(J11),"",A$7) | B11: =IF(ISBLANK(J11),"",B$7) | C11: =IF(ISBLANK(J11),"",C$7) | D11: =IF(ISBLANK(J11),"",D$7) | E11: =IF(ISBLANK(J11),"",E$7) | F11: =IF(ISBLANK(J11),"",F$7) | G11: =IF(ISBLANK(J11),"",IF(ISBLANK(G$7),"",G$7)) | H11: =IF(ISBLANK(J11),"",IF(ISBLANK(H$7),"",H$7)) | I11: 5
A12: =IF(ISBLANK(E12),"",A$2) | C12: 3 | I12: 1
A13: =IF(ISBLANK(J13),"",A$12) | B13: =IF(ISBLANK(J13),"",B$12) | C13: =IF(ISBLANK(J13),"",C$12) | D13: =IF(ISBLANK(J13),"",D$12) | E13: =IF(ISBLANK(J13),"",E$12) | F13: =IF(ISBLANK(J13),"",F$12) | G13: =IF(ISBLANK(J13),"",IF(ISBLANK(G$12),"",G$12)) | H13: =IF(ISBLANK(J13),"",IF(ISBLANK(H$12),"",H$12)) | I13: 2
A14: =IF(ISBLANK(J14),"",A$12) | B14: =IF(ISBLANK(J14),"",B$12) | C14: =IF(ISBLANK(J14),"",C$12) | D14: =IF(ISBLANK(J14),"",D$12) | E14: =IF(ISBLANK(J14),"",E$12) | F14: =IF(ISBLANK(J14),"",F$12) | G14: =IF(ISBLANK(J14),"",IF(ISBLANK(G$12),"",G$12)) | H14: =IF(ISBLANK(J14),"",IF(ISBLANK(H$12),"",H$12)) | I14: 3
A15: =IF(ISBLANK(J15),"",A$12) | B15: =IF(ISBLANK(J15),"",B$12) | C15: =IF(ISBLANK(J15),"",C$12) | D15: =IF(ISBLANK(J15),"",D$12) | E15: =IF(ISBLANK(J15),"",E$12) | F15: =IF(ISBLANK(J15),"",F$12) | G15: =IF(ISBLANK(J15),"",IF(ISBLANK(G$12),"",G$12)) | H15: =IF(ISBLANK(J15),"",IF(ISBLANK(H$12),"",H$12)) | I15: 4
A16: =IF(ISBLANK(J16),"",A$12) | B16: =IF(ISBLANK(J16),"",B$12) | C16: =IF(ISBLANK(J16),"",C$12) | D16: =IF(ISBLANK(J16),"",D$12) | E16: =IF(ISBLANK(J16),"",E$12) | F16: =IF(ISBLANK(J16),"",F$12) | G16: =IF(ISBLANK(J16),"",IF(ISBLANK(G$12),"",G$12)) | H16: =IF(ISBLANK(J16),"",IF(ISBLANK(H$12),"",H$12)) | I16: 5
A17: =IF(ISBLANK(E17),"",A$2) | C17: 4 | I17: 1
A18: =IF(ISBLANK(J18),"",A$17) | B18: =IF(ISBLANK(J18),"",B$17) | C18: =IF(ISBLANK(J18),"",C$17) | D18: =IF(ISBLANK(J18),"",D$17) | E18: =IF(ISBLANK(J18),"",E$17) | F18: =IF(ISBLANK(J18),"",F$17) | G18: =IF(ISBLANK(J18),"",IF(ISBLANK(G$17),"",G$17)) | H18: =IF(ISBLANK(J18),"",IF(ISBLANK(H$17),"",H$17)) | I18: 2
A19: =IF(ISBLANK(J19),"",A$17) | B19: =IF(ISBLANK(J19),"",B$17) | C19: =IF(ISBLANK(J19),"",C$17) | D19: =IF(ISBLANK(J19),"",D$17) | E19: =IF(ISBLANK(J19),"",E$17) | F19: =IF(ISBLANK(J19),"",F$17) | G19: =IF(ISBLANK(J19),"",IF(ISBLANK(G$17),"",G$17)) | H19: =IF(ISBLANK(J19),"",IF(ISBLANK(H$17),"",H$17)) | I19: 3
A20: =IF(ISBLANK(J20),"",A$17) | B20: =IF(ISBLANK(J20),"",B$17) | C20: =IF(ISBLANK(J20),"",C$17) | D20: =IF(ISBLANK(J20),"",D$17) | E20: =IF(ISBLANK(J20),"",E$17) | F20: =IF(ISBLANK(J20),"",F$17) | G20: =IF(ISBLANK(J20),"",IF(ISBLANK(G$17),"",G$17)) | H20: =IF(ISBLANK(J20),"",IF(ISBLANK(H$17),"",H$17)) | I20: 4
A21: =IF(ISBLANK(J21),"",A$17) | B21: =IF(ISBLANK(J21),"",B$17) | C21: =IF(ISBLANK(J21),"",C$17) | D21: =IF(ISBLANK(J21),"",D$17) | E21: =IF(ISBLANK(J21),"",E$17) | F21: =IF(ISBLANK(J21),"",F$17) | G21: =IF(ISBLANK(J21),"",IF(ISBLANK(G$17),"",G$17)) | H21: =IF(ISBLANK(J21),"",IF(ISBLANK(H$17),"",H$17)) | I21: 5
A22: =IF(ISBLANK(E22),"",A$2) | C22: 5 | I22: 1
A23: =IF(ISBLANK(J23),"",A$22) | B23: =IF(ISBLANK(J23),"",B$22) | C23: =IF(ISBLANK(J23),"",C$22) | D23: =IF(ISBLANK(J23),"",D$22) | E23: =IF(ISBLANK(J23),"",E$22) | F23: =IF(ISBLANK(J23),"",F$22) | G23: =IF(ISBLANK(J23),"",IF(ISBLANK(G$22),"",G$22)) | H23: =IF(ISBLANK(J23),"",IF(ISBLANK(H$22),"",H$22)) | I23: 2
A24: =IF(ISBLANK(J24),"",A$22) | B24: =IF(ISBLANK(J24),"",B$22) | C24: =IF(ISBLANK(J24),"",C$22) | D24: =IF(ISBLANK(J24),"",D$22) | E24: =IF(ISBLANK(J24),"",E$22) | F24: =IF(ISBLANK(J24),"",F$22) | G24: =IF(ISBLANK(J24),"",IF(ISBLANK(G$22),"",G$22)) | H24: =IF(ISBLANK(J24),"",IF(ISBLANK(H$22),"",H$22)) | I24: 3
A25: =IF(ISBLANK(J25),"",A$22) | B25: =IF(ISBLANK(J25),"",B$22) | C25: =IF(ISBLANK(J25),"",C$22) | D25: =IF(ISBLANK(J25),"",D$22) | E25: =IF(ISBLANK(J25),"",E$22) | F25: =IF(ISBLANK(J25),"",F$22) | G25: =IF(ISBLANK(J25),"",IF(ISBLANK(G$22),"",G$22)) | H25: =IF(ISBLANK(J25),"",IF(ISBLANK(H$22),"",H$22)) | I25: 4
A26: =IF(ISBLANK(J26),"",A$22) | B26: =IF(ISBLANK(J26),"",B$22) | C26: =IF(ISBLANK(J26),"",C$22) | D26: =IF(ISBLANK(J26),"",D$22) | E26: =IF(ISBLANK(J26),"",E$22) | F26: =IF(ISBLANK(J26),"",F$22) | G26: =IF(ISBLANK(J26),"",IF(ISBLANK(G$22),"",G$22)) | H26: =IF(ISBLANK(J26),"",IF(ISBLANK(H$22),"",H$22)) | I26: 5
A27: =IF(ISBLANK(E27),"",A$2) | C27: 6 | I27: 1
A28: =IF(ISBLANK(J28),"",A$27) | B28: =IF(ISBLANK(J28),"",B$27) | C28: =IF(ISBLANK(J28),"",C$27) | D28: =IF(ISBLANK(J28),"",D$27) | E28: =IF(ISBLANK(J28),"",E$27) | F28: =IF(ISBLANK(J28),"",F$27) | G28: =IF(ISBLANK(J28),"",IF(ISBLANK(G$27),"",G$27)) | H28: =IF(ISBLANK(J28),"",IF(ISBLANK(H$27),"",H$27)) | I28: 2
A29: =IF(ISBLANK(J29),"",A$27) | B29: =IF(ISBLANK(J29),"",B$27) | C29: =IF(ISBLANK(J29),"",C$27) | D29: =IF(ISBLANK(J29),"",D$27) | E29: =IF(ISBLANK(J29),"",E$27) | F29: =IF(ISBLANK(J29),"",F$27) | G29: =IF(ISBLANK(J29),"",IF(ISBLANK(G$27),"",G$27)) | H29: =IF(ISBLANK(J29),"",IF(ISBLANK(H$27),"",H$27)) | I29: 3
A30: =IF(ISBLANK(J30),"",A$27) | B30: =IF(ISBLANK(J30),"",B$27) | C30: =IF(ISBLANK(J30),"",C$27) | D30: =IF(ISBLANK(J30),"",D$27) | E30: =IF(ISBLANK(J30),"",E$27) | F30: =IF(ISBLANK(J30),"",F$27) | G30: =IF(ISBLANK(J30),"",IF(ISBLANK(G$27),"",G$27)) | H30: =IF(ISBLANK(J30),"",IF(ISBLANK(H$27),"",H$27)) | I30: 4
A31: =IF(ISBLANK(J31),"",A$27) | B31: =IF(ISBLANK(J31),"",B$27) | C31: =IF(ISBLANK(J31),"",C$27) | D31: =IF(ISBLANK(J31),"",D$27) | E31: =IF(ISBLANK(J31),"",E$27) | F31: =IF(ISBLANK(J31),"",F$27) | G31: =IF(ISBLANK(J31),"",IF(ISBLANK(G$27),"",G$27)) | H31: =IF(ISBLANK(J31),"",IF(ISBLANK(H$27),"",H$27)) | I31: 5
C32: 7 | I32: 1
A33: =IF(ISBLANK(J33),"",A$32) | B33: =IF(ISBLANK(J33),"",B$32) | C33: =IF(ISBLANK(J33),"",C$32) | D33: =IF(ISBLANK(J33),"",D$32) | E33: =IF(ISBLANK(J33),"",E$32) | F33: =IF(ISBLANK(J33),"",F$32) | G33: =IF(ISBLANK(J33),"",IF(ISBLANK(G$32),"",G$32)) | H33: =IF(ISBLANK(J33),"",IF(ISBLANK(H$32),"",H$32)) | I33: 2
A34: =IF(ISBLANK(J34),"",A$32) | B34: =IF(ISBLANK(J34),"",B$32) | C34: =IF(ISBLANK(J34),"",C$32) | D34: =IF(ISBLANK(J34),"",D$32) | E34: =IF(ISBLANK(J34),"",E$32) | F34: =IF(ISBLANK(J34),"",F$32) | G34: =IF(ISBLANK(J34),"",IF(ISBLANK(G$32),"",G$32)) | H34: =IF(ISBLANK(J34),"",IF(ISBLANK(H$32),"",H$32)) | I34: 3
A35: =IF(ISBLANK(J35),"",A$32) | B35: =IF(ISBLANK(J35),"",B$32) | C35: =IF(ISBLANK(J35),"",C$32) | D35: =IF(ISBLANK(J35),"",D$32) | E35: =IF(ISBLANK(J35),"",E$32) | F35: =IF(ISBLANK(J35),"",F$32) | G35: =IF(ISBLANK(J35),"",IF(ISBLANK(G$32),"",G$32)) | H35: =IF(ISBLANK(J35),"",IF(ISBLANK(H$32),"",H$32)) | I35: 4
A36: =IF(ISBLANK(J36),"",A$32) | B36: =IF(ISBLANK(J36),"",B$32) | C36: =IF(ISBLANK(J36),"",C$32) | D36: =IF(ISBLANK(J36),"",D$32) | E36: =IF(ISBLANK(J36),"",E$32) | F36: =IF(ISBLANK(J36),"",F$32) | G36: =IF(ISBLANK(J36),"",IF(ISBLANK(G$32),"",G$32)) | H36: =IF(ISBLANK(J36),"",IF(ISBLANK(H$32),"",H$32)) | I36: 5
A37: =IF(ISBLANK(E37),"",A$2) | C37: 8 | I37: 1
A38: =IF(ISBLANK(J38),"",A$37) | B38: =IF(ISBLANK(J38),"",B$37) | C38: =IF(ISBLANK(J38),"",C$37) | D38: =IF(ISBLANK(J38),"",D$37) | E38: =IF(ISBLANK(J38),"",E$37) | F38: =IF(ISBLANK(J38),"",F$37) | G38: =IF(ISBLANK(J38),"",IF(ISBLANK(G$37),"",G$37)) | H38: =IF(ISBLANK(J38),"",IF(ISBLANK(H$37),"",H$37)) | I38: 2
A39: =IF(ISBLANK(J39),"",A$37) | B39: =IF(ISBLANK(J39),"",B$37) | C39: =IF(ISBLANK(J39),"",C$37) | D39: =IF(ISBLANK(J39),"",D$37) | E39: =IF(ISBLANK(J39),"",E$37) | F39: =IF(ISBLANK(J39),"",F$37) | G39: =IF(ISBLANK(J39),"",IF(ISBLANK(G$37),"",G$37)) | H39: =IF(ISBLANK(J39),"",IF(ISBLANK(H$37),"",H$37)) | I39: 3
A40: =IF(ISBLANK(J40),"",A$37) | B40: =IF(ISBLANK(J40),"",B$37) | C40: =IF(ISBLANK(J40),"",C$37) | D40: =IF(ISBLANK(J40),"",D$37) | E40: =IF(ISBLANK(J40),"",E$37) | F40: =IF(ISBLANK(J40),"",F$37) | G40: =IF(ISBLANK(J40),"",IF(ISBLANK(G$37),"",G$37)) | H40: =IF(ISBLANK(J40),"",IF(ISBLANK(H$37),"",H$37)) | I40: 4
...

Sheet Daily_schedule
A1: =_xlfn.CONCAT("Schedule for ",Flight_inventory!A2) -> Schedule for
A3: Flight # Heli Manager | B3: Drop off order | C3: Plot Elevation (ft) | D3: Owner County | E3: Crew (lead in bold) | F3: Sat Phone Color Number | G3: Dist. from hub (mile) | H3: Azimuth to plot | I3: Coordinates | J3: Notes
A4: {=_xlfn._xlws.PY(0,0,Flight_inventory!A1:Q51,List_plots!A1:N301,List_phones!A1:B11,List_hub!A1:C11)} -> #VALUE!

Sheet Manifest
A1: =_xlfn.CONCAT("Manifest for ",Flight_inventory!A2) -> Manifest for
A3: {=_xlfn._xlws.PY(1,0,Flight_inventory!A1:Q51,List_gears!A1:C41,List_crew_leaders!A1:B31,List_crew_members!A1:B31)} -> #VALUE!

Sheet List_plots
A1: plot number | B1: county | C1: owner | D1: plot latitude (decimal degree) | E1: plot longitude (decimal degree) | F1: landing zone latitude (decimal degree) | G1: landing zone longitude (decimal degree) | H1: elevation | I1: slope | J1: aspect | K1: PRIORITY | L1: NEAR_HUB | M1: PlotCover | N1: PREV_INV_YEAR
A2: p1 | B2: c1 | C2: o100 | D2: 64.90462 | E2: -157.4092 | H2: 50 | I2: 0.2 | J2: 2 | K2: HIGH | L2: GALENA | M2: Forest
A3: p2 | B3: c2 | C3: o101 | D3: 64.74456 | E3: -156.13405 | H3: 55 | I3: 0.4 | J3: 4 | K3: HIGH | L3: GALENA | M3: Forest
A4: p3 | B4: c3 | C4: o102 | D4: 64.15926 | E4: -157.554 | H4: 50 | I4: 0.6 | J4: 6 | K4: HIGH | L4: GALENA | M4: Forest

Sheet List_hub
A1: name | B1: hub latitude (decimal degree) | C1: hub longitude (decimal degree)
A2: hub1 | B2: 65.183693 | C2: -157.55916
A3: hub2 | B3: 63.40793 | C3: -157.7035
A4: hub3 | B4: 66.35439 | C4: -149.5888

Sheet List_crew_leaders
A1: Name | B1: Flight weight (lbs)
A2: cl1 | B2: 150
A3: cl2 | B3: 200
A4: cl3 | B4: 130

Sheet List_crew_members
A1: Name | B1: Flight weight (lbs)
A2: cm1 | B2: 200
A3: cm2 | B3: 250
A4: cm3 | B4: 100

Sheet List_heli_managers
A1: Name | D1: yes | G1: Combined list of crew leads and members [automated]
A2: cl2 | D2: no | G2: {=_xlfn._xlws.SORT(_xlfn.UNIQUE(_xlfn.VSTACK(List_crew_leaders!A2:A31,List_crew_members!A2:A31)))} -> cl1
G3: cl2
G4: cl3
G5: cm1
G6: cm2
G7: cm3
G8: 0

Sheet List_pilots
A1: Name | B1: Flight weight (lbs)
A2: p1 | B2: 300
A3: p2 | B3: 200
A4: p3 | B4: 100

Sheet List_gears
A1: Name | B1: Description | C1: Flight weight (lbs) | I1: List of gears category | J1: Description
A2: Soil bag | B2: =_xlfn.XLOOKUP(A2,$I$2:$I$8,$J$2:$J$8,"") -> One per team | C2: 20 | I2: Bivi emergency bag | J2: One per team
A3: Personal back pack | B3: =_xlfn.XLOOKUP(A3,$I$2:$I$8,$J$2:$J$8,"") -> One per person | C3: 60 | I3: Soil bag | J3: One per team
B4: =_xlfn.XLOOKUP(A4,$I$2:$I$8,$J$2:$J$8,"") | I4: Gun | J4: One per team
B5: =_xlfn.XLOOKUP(A5,$I$2:$I$8,$J$2:$J$8,"") | I5: Bear spray / ammo can | J5: One per team
B6: =_xlfn.XLOOKUP(A6,$I$2:$I$8,$J$2:$J$8,"") | I6: Sachel | J6: One per team
B7: =_xlfn.XLOOKUP(A7,$I$2:$I$8,$J$2:$J$8,"") | I7: Personal back pack | J7: One per person
B8: =_xlfn.XLOOKUP(A8,$I$2:$I$8,$J$2:$J$8,"") | I8: Personal flight bag | J8: One per person
B9: =_xlfn.XLOOKUP(A9,$I$2:$I$8,$J$2:$J$8,"")
B10: =_xlfn.XLOOKUP(A10,$I$2:$I$8,$J$2:$J$8,"")
B11: =_xlfn.XLOOKUP(A11,$I$2:$I$8,$J$2:$J$8,"")
B12: =_xlfn.XLOOKUP(A12,$I$2:$I$8,$J$2:$J$8,"")
B13: =_xlfn.XLOOKUP(A13,$I$2:$I$8,$J$2:$J$8,"")
B14: =_xlfn.XLOOKUP(A14,$I$2:$I$8,$J$2:$J$8,"")
B15: =_xlfn.XLOOKUP(A15,$I$2:$I$8,$J$2:$J$8,"")
B16: =_xlfn.XLOOKUP(A16,$I$2:$I$8,$J$2:$J$8,"")
B17: =_xlfn.XLOOKUP(A17,$I$2:$I$8,$J$2:$J$8,"")
B18: =_xlfn.XLOOKUP(A18,$I$2:$I$8,$J$2:$J$8,"")
B19: =_xlfn.XLOOKUP(A19,$I$2:$I$8,$J$2:$J$8,"")
B20: =_xlfn.XLOOKUP(A20,$I$2:$I$8,$J$2:$J$8,"")
... B41: =_xlfn.XLOOKUP(A41,$I$2:$I$8,$J$2:$J$8,"")

Sheet List_phones
A1: Phone color | B1: Phone number
A2: red | B2: 907-699-9999
A3: blue | B3: 9078888888
